{
 "cells": [
  {
   "cell_type": "markdown",
   "metadata": {},
   "source": [
    "## Exceptions in Python\n",
    "When you encounter exceptions in Python, you may be tempted to catch them and then ignore them. This is almost always not a good strategy. The general rule is to catch the exceptions you intend to handle. If you can't handle an exception, it's better to let it occur and break the program.\n",
    "\n",
    "This notebook will explain how to catch and handle exceptions.\n",
    "\n",
    "### How Exceptions Occur\n",
    "\n",
    "They are created by invalid operations generated by Python itself or generated by your own code."
   ]
  },
  {
   "cell_type": "code",
   "execution_count": 1,
   "metadata": {},
   "outputs": [
    {
     "ename": "ZeroDivisionError",
     "evalue": "division by zero",
     "output_type": "error",
     "traceback": [
      "\u001b[31m---------------------------------------------------------------------------\u001b[39m",
      "\u001b[31mZeroDivisionError\u001b[39m                         Traceback (most recent call last)",
      "\u001b[36mCell\u001b[39m\u001b[36m \u001b[39m\u001b[32mIn[1]\u001b[39m\u001b[32m, line 2\u001b[39m\n\u001b[32m      1\u001b[39m \u001b[38;5;66;03m# exception from Python itself\u001b[39;00m\n\u001b[32m----> \u001b[39m\u001b[32m2\u001b[39m \u001b[32;43m14\u001b[39;49m\u001b[43m \u001b[49m\u001b[43m/\u001b[49m\u001b[43m \u001b[49m\u001b[32;43m0\u001b[39;49m\n",
      "\u001b[31mZeroDivisionError\u001b[39m: division by zero"
     ]
    }
   ],
   "source": [
    "# exception from Python itself\n",
    "14 / 0"
   ]
  },
  {
   "cell_type": "code",
   "execution_count": 2,
   "metadata": {},
   "outputs": [
    {
     "ename": "RuntimeError",
     "evalue": "this is a problem!",
     "output_type": "error",
     "traceback": [
      "\u001b[31m---------------------------------------------------------------------------\u001b[39m",
      "\u001b[31mRuntimeError\u001b[39m                              Traceback (most recent call last)",
      "\u001b[36mCell\u001b[39m\u001b[36m \u001b[39m\u001b[32mIn[2]\u001b[39m\u001b[32m, line 2\u001b[39m\n\u001b[32m      1\u001b[39m \u001b[38;5;66;03m# Throwing an exception with your own code\u001b[39;00m\n\u001b[32m----> \u001b[39m\u001b[32m2\u001b[39m \u001b[38;5;28;01mraise\u001b[39;00m \u001b[38;5;167;01mRuntimeError\u001b[39;00m(\u001b[33m\"\u001b[39m\u001b[33mthis is a problem!\u001b[39m\u001b[33m\"\u001b[39m)\n",
      "\u001b[31mRuntimeError\u001b[39m: this is a problem!"
     ]
    }
   ],
   "source": [
    "# Throwing an exception with your own code\n",
    "raise RuntimeError(\"this is a problem!\")"
   ]
  },
  {
   "cell_type": "markdown",
   "metadata": {},
   "source": [
    "### Catching an Exception\n",
    "\n",
    "You'll need the `try` and `except` keywords to catch exceptions. The general rule is to always catch the exception or exceptions (plural!) you need. Don't leave the catch \"naked\" (shown later in this notebook)."
   ]
  },
  {
   "cell_type": "code",
   "execution_count": 3,
   "metadata": {},
   "outputs": [
    {
     "name": "stdout",
     "output_type": "stream",
     "text": [
      "You can divide a number by zero\n",
      "None\n"
     ]
    }
   ],
   "source": [
    "try:\n",
    "    # some operation that may cause an error\n",
    "    result = 14 / 0\n",
    "except ZeroDivisionError:\n",
    "    # Once the exception is caught, some further operation can be performed\n",
    "    print(\"You can divide a number by zero\")\n",
    "    # result = 14 / 2\n",
    "    result = None\n",
    "\n",
    "print(result)"
   ]
  },
  {
   "cell_type": "code",
   "execution_count": 4,
   "metadata": {},
   "outputs": [
    {
     "name": "stdout",
     "output_type": "stream",
     "text": [
      "7.0\n"
     ]
    }
   ],
   "source": [
    "# don't get tempted to catch all exceptions \n",
    "try:\n",
    "    # some operation that may cause an error\n",
    "    result = 14 / 0\n",
    "    raise RuntimeError(\"error!\") \n",
    "except Exception:\n",
    "    # Once the exception is caught, some further operation can be performed\n",
    "    result = 14 / 2\n",
    "    # result = None\n",
    "\n",
    "print(result)"
   ]
  },
  {
   "cell_type": "markdown",
   "metadata": {},
   "source": [
    "### Catching multiple Exceptions\n",
    "\n",
    "You can group many exceptions when catching them as well as doing an assignment if needed"
   ]
  },
  {
   "cell_type": "code",
   "execution_count": 5,
   "metadata": {},
   "outputs": [
    {
     "ename": "TypeError",
     "evalue": "unsupported operand type(s) for +: 'float' and 'str'",
     "output_type": "error",
     "traceback": [
      "\u001b[31m---------------------------------------------------------------------------\u001b[39m",
      "\u001b[31mTypeError\u001b[39m                                 Traceback (most recent call last)",
      "\u001b[36mCell\u001b[39m\u001b[36m \u001b[39m\u001b[32mIn[5]\u001b[39m\u001b[32m, line 4\u001b[39m\n\u001b[32m      1\u001b[39m \u001b[38;5;28;01mtry\u001b[39;00m:\n\u001b[32m      2\u001b[39m     \u001b[38;5;66;03m# some operation that may cause an error\u001b[39;00m\n\u001b[32m      3\u001b[39m     result = \u001b[32m14\u001b[39m / \u001b[32m2\u001b[39m \n\u001b[32m----> \u001b[39m\u001b[32m4\u001b[39m     \u001b[43mresult\u001b[49m\u001b[43m \u001b[49m\u001b[43m+\u001b[49m\u001b[43m \u001b[49m\u001b[33;43m\"\u001b[39;49m\u001b[33;43m100\u001b[39;49m\u001b[33;43m\"\u001b[39;49m\n\u001b[32m      5\u001b[39m \u001b[38;5;28;01mexcept\u001b[39;00m \u001b[38;5;167;01mZeroDivisionError\u001b[39;00m:\n\u001b[32m      6\u001b[39m     \u001b[38;5;66;03m# Once the exception is caught, some further operation can be performed\u001b[39;00m\n\u001b[32m      7\u001b[39m     result = \u001b[32m14\u001b[39m / \u001b[32m2\u001b[39m\n",
      "\u001b[31mTypeError\u001b[39m: unsupported operand type(s) for +: 'float' and 'str'"
     ]
    }
   ],
   "source": [
    "try:\n",
    "    # some operation that may cause an error\n",
    "    result = 14 / 2 \n",
    "    result + \"100\"\n",
    "except ZeroDivisionError:\n",
    "    # Once the exception is caught, some further operation can be performed\n",
    "    result = 14 / 2\n",
    "\n",
    "print(result)"
   ]
  },
  {
   "cell_type": "code",
   "execution_count": 6,
   "metadata": {},
   "outputs": [
    {
     "name": "stdout",
     "output_type": "stream",
     "text": [
      "got an error --> division by zero\n",
      "7.0\n"
     ]
    }
   ],
   "source": [
    "# Assign the resulting exception to a variable\n",
    "try:\n",
    "    # some operation that may cause an error\n",
    "    result = 14 / 0 \n",
    "except ZeroDivisionError as error:\n",
    "    # Once the exception is caught, some further operation can be performed\n",
    "    print(f\"got an error --> {error}\")\n",
    "    result = 14 / 2\n",
    "\n",
    "print(result)"
   ]
  }
 ],
 "metadata": {
  "kernelspec": {
   "display_name": "ai-course-env",
   "language": "python",
   "name": "python3"
  },
  "language_info": {
   "codemirror_mode": {
    "name": "ipython",
    "version": 3
   },
   "file_extension": ".py",
   "mimetype": "text/x-python",
   "name": "python",
   "nbconvert_exporter": "python",
   "pygments_lexer": "ipython3",
   "version": "3.12.10"
  }
 },
 "nbformat": 4,
 "nbformat_minor": 2
}
